[2024-10-18T19:16:59.643+0000] {local_task_job_runner.py:123} INFO - ::group::Pre task execution logs
[2024-10-18T19:16:59.679+0000] {taskinstance.py:2612} INFO - Dependencies all met for dep_context=non-requeueable deps ti=<TaskInstance: post_gres_dag.print_this_context manual__2024-10-18T19:16:57.311826+00:00 [queued]>
[2024-10-18T19:16:59.699+0000] {taskinstance.py:2612} INFO - Dependencies all met for dep_context=requeueable deps ti=<TaskInstance: post_gres_dag.print_this_context manual__2024-10-18T19:16:57.311826+00:00 [queued]>
[2024-10-18T19:16:59.710+0000] {taskinstance.py:2865} INFO - Starting attempt 1 of 1
[2024-10-18T19:16:59.738+0000] {taskinstance.py:2888} INFO - Executing <Task(PostgresOperator): print_this_context> on 2024-10-18 19:16:57.311826+00:00
[2024-10-18T19:16:59.750+0000] {warnings.py:112} WARNING - /home/***/.local/lib/python3.12/site-packages/***/task/task_runner/standard_task_runner.py:70: DeprecationWarning: This process (pid=1536) is multi-threaded, use of fork() may lead to deadlocks in the child.
  pid = os.fork()

[2024-10-18T19:16:59.754+0000] {standard_task_runner.py:104} INFO - Running: ['***', 'tasks', 'run', 'post_gres_dag', 'print_this_context', 'manual__2024-10-18T19:16:57.311826+00:00', '--job-id', '17', '--raw', '--subdir', 'DAGS_FOLDER/post_gres.py', '--cfg-path', '/tmp/tmpbs91ymlb']
[2024-10-18T19:16:59.755+0000] {standard_task_runner.py:72} INFO - Started process 1538 to run task
[2024-10-18T19:16:59.757+0000] {standard_task_runner.py:105} INFO - Job 17: Subtask print_this_context
[2024-10-18T19:16:59.828+0000] {task_command.py:467} INFO - Running <TaskInstance: post_gres_dag.print_this_context manual__2024-10-18T19:16:57.311826+00:00 [running]> on host d004819e31a5
[2024-10-18T19:16:59.912+0000] {taskinstance.py:3131} INFO - Exporting env vars: AIRFLOW_CTX_DAG_OWNER='***' AIRFLOW_CTX_DAG_ID='post_gres_dag' AIRFLOW_CTX_TASK_ID='print_this_context' AIRFLOW_CTX_EXECUTION_DATE='2024-10-18T19:16:57.311826+00:00' AIRFLOW_CTX_TRY_NUMBER='1' AIRFLOW_CTX_DAG_RUN_ID='manual__2024-10-18T19:16:57.311826+00:00'
[2024-10-18T19:16:59.915+0000] {logging_mixin.py:190} INFO - Task instance is in running state
[2024-10-18T19:16:59.917+0000] {logging_mixin.py:190} INFO -  Previous state of the Task instance: queued
[2024-10-18T19:16:59.918+0000] {logging_mixin.py:190} INFO - Current task name:print_this_context state:running start_date:2024-10-18 19:16:59.682180+00:00
[2024-10-18T19:16:59.920+0000] {logging_mixin.py:190} INFO - Dag name:post_gres_dag and current dag run status:running
[2024-10-18T19:16:59.922+0000] {taskinstance.py:731} INFO - ::endgroup::
[2024-10-18T19:16:59.924+0000] {sql.py:266} INFO - Executing: CREATE TABLE IF NOT 
EXISTS my_books( id SERIAL PRIMARY KEY, title TEXT NOTNULL, pages INT);
[2024-10-18T19:16:59.940+0000] {base.py:84} INFO - Retrieving connection 'books'
[2024-10-18T19:16:59.967+0000] {base.py:84} INFO - Retrieving connection 'books'
[2024-10-18T19:16:59.975+0000] {taskinstance.py:3310} ERROR - Task failed with exception
Traceback (most recent call last):
  File "/home/airflow/.local/lib/python3.12/site-packages/airflow/models/taskinstance.py", line 767, in _execute_task
    result = _execute_callable(context=context, **execute_callable_kwargs)
             ^^^^^^^^^^^^^^^^^^^^^^^^^^^^^^^^^^^^^^^^^^^^^^^^^^^^^^^^^^^^^
  File "/home/airflow/.local/lib/python3.12/site-packages/airflow/models/taskinstance.py", line 733, in _execute_callable
    return ExecutionCallableRunner(
           ^^^^^^^^^^^^^^^^^^^^^^^^
  File "/home/airflow/.local/lib/python3.12/site-packages/airflow/utils/operator_helpers.py", line 252, in run
    return self.func(*args, **kwargs)
           ^^^^^^^^^^^^^^^^^^^^^^^^^^
  File "/home/airflow/.local/lib/python3.12/site-packages/airflow/models/baseoperator.py", line 406, in wrapper
    return func(self, *args, **kwargs)
           ^^^^^^^^^^^^^^^^^^^^^^^^^^^
  File "/home/airflow/.local/lib/python3.12/site-packages/airflow/providers/common/sql/operators/sql.py", line 272, in execute
    output = hook.run(
             ^^^^^^^^^
  File "/home/airflow/.local/lib/python3.12/site-packages/airflow/providers/common/sql/hooks/sql.py", line 452, in run
    with self._create_autocommit_connection(autocommit) as conn:
         ^^^^^^^^^^^^^^^^^^^^^^^^^^^^^^^^^^^^^^^^^^^^^^
  File "/usr/local/lib/python3.12/contextlib.py", line 137, in __enter__
    return next(self.gen)
           ^^^^^^^^^^^^^^
  File "/home/airflow/.local/lib/python3.12/site-packages/airflow/providers/common/sql/hooks/sql.py", line 574, in _create_autocommit_connection
    with closing(self.get_conn()) as conn:
                 ^^^^^^^^^^^^^^^
  File "/home/airflow/.local/lib/python3.12/site-packages/airflow/providers/postgres/hooks/postgres.py", line 176, in get_conn
    self.conn = psycopg2.connect(**conn_args)
                ^^^^^^^^^^^^^^^^^^^^^^^^^^^^^
  File "/home/airflow/.local/lib/python3.12/site-packages/psycopg2/__init__.py", line 122, in connect
    conn = _connect(dsn, connection_factory=connection_factory, **kwasync)
           ^^^^^^^^^^^^^^^^^^^^^^^^^^^^^^^^^^^^^^^^^^^^^^^^^^^^^^^^^^^^^^^
psycopg2.OperationalError: connection to server at "172.21.0.3", port 5432 failed: FATAL:  database "pg_db" does not exist

[2024-10-18T19:16:59.995+0000] {logging_mixin.py:190} INFO - Task instance in failure state
[2024-10-18T19:16:59.997+0000] {logging_mixin.py:190} INFO - Task start:2024-10-18 19:16:59.682180+00:00 end:2024-10-18 19:16:59.994654+00:00 duration:0.312474
[2024-10-18T19:17:00.000+0000] {logging_mixin.py:190} INFO - Task:<Task(PostgresOperator): print_this_context> dag:<DAG: post_gres_dag> dagrun:<DagRun post_gres_dag @ 2024-10-18 19:16:57.311826+00:00: manual__2024-10-18T19:16:57.311826+00:00, state:running, queued_at: 2024-10-18 19:16:57.370631+00:00. externally triggered: True>
[2024-10-18T19:17:00.002+0000] {logging_mixin.py:190} INFO - Failure caused by connection to server at "172.21.0.3", port 5432 failed: FATAL:  database "pg_db" does not exist
[2024-10-18T19:17:00.012+0000] {taskinstance.py:1225} INFO - Marking task as FAILED. dag_id=post_gres_dag, task_id=print_this_context, run_id=manual__2024-10-18T19:16:57.311826+00:00, execution_date=20241018T191657, start_date=20241018T191659, end_date=20241018T191659
[2024-10-18T19:17:00.049+0000] {taskinstance.py:340} INFO - ::group::Post task execution logs
[2024-10-18T19:17:00.053+0000] {standard_task_runner.py:124} ERROR - Failed to execute job 17 for task print_this_context (connection to server at "172.21.0.3", port 5432 failed: FATAL:  database "pg_db" does not exist
; 1538)
Traceback (most recent call last):
  File "/home/airflow/.local/lib/python3.12/site-packages/airflow/task/task_runner/standard_task_runner.py", line 117, in _start_by_fork
    ret = args.func(args, dag=self.dag)
          ^^^^^^^^^^^^^^^^^^^^^^^^^^^^^
  File "/home/airflow/.local/lib/python3.12/site-packages/airflow/cli/cli_config.py", line 49, in command
    return func(*args, **kwargs)
           ^^^^^^^^^^^^^^^^^^^^^
  File "/home/airflow/.local/lib/python3.12/site-packages/airflow/utils/cli.py", line 115, in wrapper
    return f(*args, **kwargs)
           ^^^^^^^^^^^^^^^^^^
  File "/home/airflow/.local/lib/python3.12/site-packages/airflow/cli/commands/task_command.py", line 483, in task_run
    task_return_code = _run_task_by_selected_method(args, _dag, ti)
                       ^^^^^^^^^^^^^^^^^^^^^^^^^^^^^^^^^^^^^^^^^^^^
  File "/home/airflow/.local/lib/python3.12/site-packages/airflow/cli/commands/task_command.py", line 256, in _run_task_by_selected_method
    return _run_raw_task(args, ti)
           ^^^^^^^^^^^^^^^^^^^^^^^
  File "/home/airflow/.local/lib/python3.12/site-packages/airflow/cli/commands/task_command.py", line 341, in _run_raw_task
    return ti._run_raw_task(
           ^^^^^^^^^^^^^^^^^
  File "/home/airflow/.local/lib/python3.12/site-packages/airflow/utils/session.py", line 97, in wrapper
    return func(*args, session=session, **kwargs)
           ^^^^^^^^^^^^^^^^^^^^^^^^^^^^^^^^^^^^^^
  File "/home/airflow/.local/lib/python3.12/site-packages/airflow/models/taskinstance.py", line 3004, in _run_raw_task
    return _run_raw_task(
           ^^^^^^^^^^^^^^
  File "/home/airflow/.local/lib/python3.12/site-packages/airflow/models/taskinstance.py", line 273, in _run_raw_task
    TaskInstance._execute_task_with_callbacks(
  File "/home/airflow/.local/lib/python3.12/site-packages/airflow/models/taskinstance.py", line 3158, in _execute_task_with_callbacks
    result = self._execute_task(context, task_orig)
             ^^^^^^^^^^^^^^^^^^^^^^^^^^^^^^^^^^^^^^
  File "/home/airflow/.local/lib/python3.12/site-packages/airflow/models/taskinstance.py", line 3182, in _execute_task
    return _execute_task(self, context, task_orig)
           ^^^^^^^^^^^^^^^^^^^^^^^^^^^^^^^^^^^^^^^
  File "/home/airflow/.local/lib/python3.12/site-packages/airflow/models/taskinstance.py", line 767, in _execute_task
    result = _execute_callable(context=context, **execute_callable_kwargs)
             ^^^^^^^^^^^^^^^^^^^^^^^^^^^^^^^^^^^^^^^^^^^^^^^^^^^^^^^^^^^^^
  File "/home/airflow/.local/lib/python3.12/site-packages/airflow/models/taskinstance.py", line 733, in _execute_callable
    return ExecutionCallableRunner(
           ^^^^^^^^^^^^^^^^^^^^^^^^
  File "/home/airflow/.local/lib/python3.12/site-packages/airflow/utils/operator_helpers.py", line 252, in run
    return self.func(*args, **kwargs)
           ^^^^^^^^^^^^^^^^^^^^^^^^^^
  File "/home/airflow/.local/lib/python3.12/site-packages/airflow/models/baseoperator.py", line 406, in wrapper
    return func(self, *args, **kwargs)
           ^^^^^^^^^^^^^^^^^^^^^^^^^^^
  File "/home/airflow/.local/lib/python3.12/site-packages/airflow/providers/common/sql/operators/sql.py", line 272, in execute
    output = hook.run(
             ^^^^^^^^^
  File "/home/airflow/.local/lib/python3.12/site-packages/airflow/providers/common/sql/hooks/sql.py", line 452, in run
    with self._create_autocommit_connection(autocommit) as conn:
         ^^^^^^^^^^^^^^^^^^^^^^^^^^^^^^^^^^^^^^^^^^^^^^
  File "/usr/local/lib/python3.12/contextlib.py", line 137, in __enter__
    return next(self.gen)
           ^^^^^^^^^^^^^^
  File "/home/airflow/.local/lib/python3.12/site-packages/airflow/providers/common/sql/hooks/sql.py", line 574, in _create_autocommit_connection
    with closing(self.get_conn()) as conn:
                 ^^^^^^^^^^^^^^^
  File "/home/airflow/.local/lib/python3.12/site-packages/airflow/providers/postgres/hooks/postgres.py", line 176, in get_conn
    self.conn = psycopg2.connect(**conn_args)
                ^^^^^^^^^^^^^^^^^^^^^^^^^^^^^
  File "/home/airflow/.local/lib/python3.12/site-packages/psycopg2/__init__.py", line 122, in connect
    conn = _connect(dsn, connection_factory=connection_factory, **kwasync)
           ^^^^^^^^^^^^^^^^^^^^^^^^^^^^^^^^^^^^^^^^^^^^^^^^^^^^^^^^^^^^^^^
psycopg2.OperationalError: connection to server at "172.21.0.3", port 5432 failed: FATAL:  database "pg_db" does not exist

[2024-10-18T19:17:00.099+0000] {local_task_job_runner.py:266} INFO - Task exited with return code 1
[2024-10-18T19:17:00.126+0000] {taskinstance.py:3900} INFO - 0 downstream tasks scheduled from follow-on schedule check
[2024-10-18T19:17:00.130+0000] {local_task_job_runner.py:245} INFO - ::endgroup::
