[2024-10-18T19:23:26.501+0000] {local_task_job_runner.py:123} INFO - ::group::Pre task execution logs
[2024-10-18T19:23:26.539+0000] {taskinstance.py:2612} INFO - Dependencies all met for dep_context=non-requeueable deps ti=<TaskInstance: post_gres_dag.print_this_context manual__2024-10-18T19:23:11.894647+00:00 [queued]>
[2024-10-18T19:23:26.561+0000] {taskinstance.py:2612} INFO - Dependencies all met for dep_context=requeueable deps ti=<TaskInstance: post_gres_dag.print_this_context manual__2024-10-18T19:23:11.894647+00:00 [queued]>
[2024-10-18T19:23:26.573+0000] {taskinstance.py:2865} INFO - Starting attempt 1 of 1
[2024-10-18T19:23:26.601+0000] {taskinstance.py:2888} INFO - Executing <Task(PostgresOperator): print_this_context> on 2024-10-18 19:23:11.894647+00:00
[2024-10-18T19:23:26.614+0000] {warnings.py:112} WARNING - /home/***/.local/lib/python3.12/site-packages/***/task/task_runner/standard_task_runner.py:70: DeprecationWarning: This process (pid=82) is multi-threaded, use of fork() may lead to deadlocks in the child.
  pid = os.fork()

[2024-10-18T19:23:26.617+0000] {standard_task_runner.py:104} INFO - Running: ['***', 'tasks', 'run', 'post_gres_dag', 'print_this_context', 'manual__2024-10-18T19:23:11.894647+00:00', '--job-id', '23', '--raw', '--subdir', 'DAGS_FOLDER/post_gres.py', '--cfg-path', '/tmp/tmpmtzdx1m1']
[2024-10-18T19:23:26.619+0000] {standard_task_runner.py:72} INFO - Started process 84 to run task
[2024-10-18T19:23:26.622+0000] {standard_task_runner.py:105} INFO - Job 23: Subtask print_this_context
[2024-10-18T19:23:26.756+0000] {task_command.py:467} INFO - Running <TaskInstance: post_gres_dag.print_this_context manual__2024-10-18T19:23:11.894647+00:00 [running]> on host d004819e31a5
[2024-10-18T19:23:26.942+0000] {taskinstance.py:3131} INFO - Exporting env vars: AIRFLOW_CTX_DAG_OWNER='***' AIRFLOW_CTX_DAG_ID='post_gres_dag' AIRFLOW_CTX_TASK_ID='print_this_context' AIRFLOW_CTX_EXECUTION_DATE='2024-10-18T19:23:11.894647+00:00' AIRFLOW_CTX_TRY_NUMBER='1' AIRFLOW_CTX_DAG_RUN_ID='manual__2024-10-18T19:23:11.894647+00:00'
[2024-10-18T19:23:26.948+0000] {logging_mixin.py:190} INFO - Task instance is in running state
[2024-10-18T19:23:26.953+0000] {logging_mixin.py:190} INFO -  Previous state of the Task instance: queued
[2024-10-18T19:23:26.956+0000] {logging_mixin.py:190} INFO - Current task name:print_this_context state:running start_date:2024-10-18 19:23:26.545037+00:00
[2024-10-18T19:23:26.960+0000] {logging_mixin.py:190} INFO - Dag name:post_gres_dag and current dag run status:running
[2024-10-18T19:23:26.963+0000] {taskinstance.py:731} INFO - ::endgroup::
[2024-10-18T19:23:26.966+0000] {sql.py:266} INFO - Executing: CREATE TABLE IF NOT 
EXISTS my_books( id SERIAL PRIMARY KEY, title TEXT NOTNULL, pages INT);
[2024-10-18T19:23:27.003+0000] {taskinstance.py:3310} ERROR - Task failed with exception
Traceback (most recent call last):
  File "/home/airflow/.local/lib/python3.12/site-packages/airflow/models/taskinstance.py", line 767, in _execute_task
    result = _execute_callable(context=context, **execute_callable_kwargs)
             ^^^^^^^^^^^^^^^^^^^^^^^^^^^^^^^^^^^^^^^^^^^^^^^^^^^^^^^^^^^^^
  File "/home/airflow/.local/lib/python3.12/site-packages/airflow/models/taskinstance.py", line 733, in _execute_callable
    return ExecutionCallableRunner(
           ^^^^^^^^^^^^^^^^^^^^^^^^
  File "/home/airflow/.local/lib/python3.12/site-packages/airflow/utils/operator_helpers.py", line 252, in run
    return self.func(*args, **kwargs)
           ^^^^^^^^^^^^^^^^^^^^^^^^^^
  File "/home/airflow/.local/lib/python3.12/site-packages/airflow/models/baseoperator.py", line 406, in wrapper
    return func(self, *args, **kwargs)
           ^^^^^^^^^^^^^^^^^^^^^^^^^^^
  File "/home/airflow/.local/lib/python3.12/site-packages/airflow/providers/common/sql/operators/sql.py", line 267, in execute
    hook = self.get_db_hook()
           ^^^^^^^^^^^^^^^^^^
  File "/home/airflow/.local/lib/python3.12/site-packages/airflow/providers/common/sql/operators/sql.py", line 178, in get_db_hook
    return self._hook
           ^^^^^^^^^^
  File "/usr/local/lib/python3.12/functools.py", line 993, in __get__
    val = self.func(instance)
          ^^^^^^^^^^^^^^^^^^^
  File "/home/airflow/.local/lib/python3.12/site-packages/airflow/providers/common/sql/operators/sql.py", line 153, in _hook
    conn = BaseHook.get_connection(conn_id)
           ^^^^^^^^^^^^^^^^^^^^^^^^^^^^^^^^
  File "/home/airflow/.local/lib/python3.12/site-packages/airflow/hooks/base.py", line 83, in get_connection
    conn = Connection.get_connection_from_secrets(conn_id)
           ^^^^^^^^^^^^^^^^^^^^^^^^^^^^^^^^^^^^^^^^^^^^^^^
  File "/home/airflow/.local/lib/python3.12/site-packages/airflow/models/connection.py", line 537, in get_connection_from_secrets
    raise AirflowNotFoundException(f"The conn_id `{conn_id}` isn't defined")
airflow.exceptions.AirflowNotFoundException: The conn_id `books` isn't defined
[2024-10-18T19:23:27.016+0000] {logging_mixin.py:190} INFO - Task instance in failure state
[2024-10-18T19:23:27.020+0000] {logging_mixin.py:190} INFO - Task start:2024-10-18 19:23:26.545037+00:00 end:2024-10-18 19:23:27.015664+00:00 duration:0.470627
[2024-10-18T19:23:27.024+0000] {logging_mixin.py:190} INFO - Task:<Task(PostgresOperator): print_this_context> dag:<DAG: post_gres_dag> dagrun:<DagRun post_gres_dag @ 2024-10-18 19:23:11.894647+00:00: manual__2024-10-18T19:23:11.894647+00:00, state:running, queued_at: 2024-10-18 19:23:11.916079+00:00. externally triggered: True>
[2024-10-18T19:23:27.027+0000] {logging_mixin.py:190} INFO - Failure caused by The conn_id `books` isn't defined
[2024-10-18T19:23:27.030+0000] {taskinstance.py:1225} INFO - Marking task as FAILED. dag_id=post_gres_dag, task_id=print_this_context, run_id=manual__2024-10-18T19:23:11.894647+00:00, execution_date=20241018T192311, start_date=20241018T192326, end_date=20241018T192327
[2024-10-18T19:23:27.065+0000] {taskinstance.py:340} INFO - ::group::Post task execution logs
[2024-10-18T19:23:27.070+0000] {standard_task_runner.py:124} ERROR - Failed to execute job 23 for task print_this_context (The conn_id `books` isn't defined; 84)
Traceback (most recent call last):
  File "/home/airflow/.local/lib/python3.12/site-packages/airflow/task/task_runner/standard_task_runner.py", line 117, in _start_by_fork
    ret = args.func(args, dag=self.dag)
          ^^^^^^^^^^^^^^^^^^^^^^^^^^^^^
  File "/home/airflow/.local/lib/python3.12/site-packages/airflow/cli/cli_config.py", line 49, in command
    return func(*args, **kwargs)
           ^^^^^^^^^^^^^^^^^^^^^
  File "/home/airflow/.local/lib/python3.12/site-packages/airflow/utils/cli.py", line 115, in wrapper
    return f(*args, **kwargs)
           ^^^^^^^^^^^^^^^^^^
  File "/home/airflow/.local/lib/python3.12/site-packages/airflow/cli/commands/task_command.py", line 483, in task_run
    task_return_code = _run_task_by_selected_method(args, _dag, ti)
                       ^^^^^^^^^^^^^^^^^^^^^^^^^^^^^^^^^^^^^^^^^^^^
  File "/home/airflow/.local/lib/python3.12/site-packages/airflow/cli/commands/task_command.py", line 256, in _run_task_by_selected_method
    return _run_raw_task(args, ti)
           ^^^^^^^^^^^^^^^^^^^^^^^
  File "/home/airflow/.local/lib/python3.12/site-packages/airflow/cli/commands/task_command.py", line 341, in _run_raw_task
    return ti._run_raw_task(
           ^^^^^^^^^^^^^^^^^
  File "/home/airflow/.local/lib/python3.12/site-packages/airflow/utils/session.py", line 97, in wrapper
    return func(*args, session=session, **kwargs)
           ^^^^^^^^^^^^^^^^^^^^^^^^^^^^^^^^^^^^^^
  File "/home/airflow/.local/lib/python3.12/site-packages/airflow/models/taskinstance.py", line 3004, in _run_raw_task
    return _run_raw_task(
           ^^^^^^^^^^^^^^
  File "/home/airflow/.local/lib/python3.12/site-packages/airflow/models/taskinstance.py", line 273, in _run_raw_task
    TaskInstance._execute_task_with_callbacks(
  File "/home/airflow/.local/lib/python3.12/site-packages/airflow/models/taskinstance.py", line 3158, in _execute_task_with_callbacks
    result = self._execute_task(context, task_orig)
             ^^^^^^^^^^^^^^^^^^^^^^^^^^^^^^^^^^^^^^
  File "/home/airflow/.local/lib/python3.12/site-packages/airflow/models/taskinstance.py", line 3182, in _execute_task
    return _execute_task(self, context, task_orig)
           ^^^^^^^^^^^^^^^^^^^^^^^^^^^^^^^^^^^^^^^
  File "/home/airflow/.local/lib/python3.12/site-packages/airflow/models/taskinstance.py", line 767, in _execute_task
    result = _execute_callable(context=context, **execute_callable_kwargs)
             ^^^^^^^^^^^^^^^^^^^^^^^^^^^^^^^^^^^^^^^^^^^^^^^^^^^^^^^^^^^^^
  File "/home/airflow/.local/lib/python3.12/site-packages/airflow/models/taskinstance.py", line 733, in _execute_callable
    return ExecutionCallableRunner(
           ^^^^^^^^^^^^^^^^^^^^^^^^
  File "/home/airflow/.local/lib/python3.12/site-packages/airflow/utils/operator_helpers.py", line 252, in run
    return self.func(*args, **kwargs)
           ^^^^^^^^^^^^^^^^^^^^^^^^^^
  File "/home/airflow/.local/lib/python3.12/site-packages/airflow/models/baseoperator.py", line 406, in wrapper
    return func(self, *args, **kwargs)
           ^^^^^^^^^^^^^^^^^^^^^^^^^^^
  File "/home/airflow/.local/lib/python3.12/site-packages/airflow/providers/common/sql/operators/sql.py", line 267, in execute
    hook = self.get_db_hook()
           ^^^^^^^^^^^^^^^^^^
  File "/home/airflow/.local/lib/python3.12/site-packages/airflow/providers/common/sql/operators/sql.py", line 178, in get_db_hook
    return self._hook
           ^^^^^^^^^^
  File "/usr/local/lib/python3.12/functools.py", line 993, in __get__
    val = self.func(instance)
          ^^^^^^^^^^^^^^^^^^^
  File "/home/airflow/.local/lib/python3.12/site-packages/airflow/providers/common/sql/operators/sql.py", line 153, in _hook
    conn = BaseHook.get_connection(conn_id)
           ^^^^^^^^^^^^^^^^^^^^^^^^^^^^^^^^
  File "/home/airflow/.local/lib/python3.12/site-packages/airflow/hooks/base.py", line 83, in get_connection
    conn = Connection.get_connection_from_secrets(conn_id)
           ^^^^^^^^^^^^^^^^^^^^^^^^^^^^^^^^^^^^^^^^^^^^^^^
  File "/home/airflow/.local/lib/python3.12/site-packages/airflow/models/connection.py", line 537, in get_connection_from_secrets
    raise AirflowNotFoundException(f"The conn_id `{conn_id}` isn't defined")
airflow.exceptions.AirflowNotFoundException: The conn_id `books` isn't defined
[2024-10-18T19:23:27.127+0000] {local_task_job_runner.py:266} INFO - Task exited with return code 1
[2024-10-18T19:23:27.165+0000] {taskinstance.py:3900} INFO - 0 downstream tasks scheduled from follow-on schedule check
[2024-10-18T19:23:27.172+0000] {local_task_job_runner.py:245} INFO - ::endgroup::
